<?xml version='1.0'?>
<robot xmlns:xacro="http://www.ros.org/wiki/xacro">
<xacro:include filename="$(find rome_base_description)/model/rim.xacro"/>
<xacro:macro name="connector" params="name parent xyz rpy">
  <link name="C${name}">
    <inertial>
      <origin xyz="0 0 0.0286" rpy="0 0 0" />
      <mass value="0.092"/>
      <inertia ixx="4.8343e-05" ixy="0.0" ixz="0.0" iyy="4.8343e-05" iyz="0.0" izz="4.6517e-05"/>
    </inertial>

    <visual>
      <origin xyz="0 0 0.0286" rpy="0 0 0" />
      <geometry>
        <cylinder radius="0.0318" length="0.0572"/>
      </geometry>
    </visual>

  </link>

  <joint name="${parent}_C${name}_joint" type="continuous">
    <parent link="${parent}"/>
    <child link="C${name}"/>
    <origin xyz = "${xyz}" rpy = "${rpy}"/>
    <axis xyz = "0 0 1"/>
  </joint>

  <!-- Wheel Rims -->
  <xacro:rim name="wheel_${name}" parent="C${name}" xyz="0 0 0.0572" rpy="0 0 0"/>
 
  <gazebo reference="C${name}">
    <visual>
      <material>
        <ambient>0.7 0.7 0.7 1</ambient>
        <diffuse>0.7 0.7 0.7 1</diffuse>
        <specular>0.7 0.7 0.7 1</specular>
      </material>
    </visual>
  </gazebo>

</xacro:macro>
</robot>
